Workbook

Sheet Instrucciones
A1: Plantilla de diseño de iflow — SAP Integration Suite
A3: Cómo usar esta plantilla:
A4: 1. Ve a la hoja "Pasos del iflow" y rellena una fila por cada paso, en el orden en que deben ejecutarse. La columna
A5: "Orden" es el identificador de cada fila — el resto de hojas y columnas lo usan para referenciar unas filas desde otras.
A6: 2. En "Tipo de componente" elige SIEMPRE un valor de la lista desplegable (misma lista que "Catálogo de componentes").
A7: No escribas texto libre ahí — son exactamente los tipos que la aplicación sabe construir.
A8: 3. Rellena el resto de columnas con el detalle que conozcas. Si no conoces un dato todavía, déjalo en blanco — la IA lo
A9: marcará en "warnings" como algo pendiente de configurar, en vez de inventarlo.
A10: 4. Columna "Contenedor" — de qué parte del iflow forma parte esta fila:
A11: • "Principal": el flujo normal — ya viene puesto por defecto en toda fila nueva, así que la columna siempre queda
A12: informada; solo cámbialo si el paso va dentro de un contenedor concreto (ver los dos puntos siguientes).
A13: • El número de "Orden" de una fila "error-subprocess": esta fila solo se ejecuta si algo falla en ese bloque de errores
... A37: (Contenedor=8, van DENTRO del manejo de errores).

Sheet Pasos del iflow
A1: Orden | B1: Tipo de componente | C1: Nombre del paso | D1: Contenedor (Orden del Local Process / error-subprocess) | E1: Sistema origen/destino | F1: Dirección (Sender/Receiver) | G1: Configuración clave | H1: Condición / Notas
A2: 1 | B2: timer-start-event | C2: Inicio ejecución (job diario, modalidad Delta) | D2: Principal | G2: Job diario en modalidad Delta; property externa "person_id_external" permite forzar ejecución bajo demanda para una lista de IDs de empleado separados por coma | H2: La exportación se dispara tras el Deploy del proceso
A3: 2 | B3: groovy-script | C3: Inicializar variables globales y properties del entorno | D3: Principal | G3: Inicializa las variables globales del proceso (ausencias, errores...) y lee las properties externalizadas por entorno
A4: 3 | B4: groovy-script | C4: Resolver Value Mapping de tipos de ausencia | D4: Principal | G4: Usa el Value Mapping "VM-Tipo_Absentismos_TEST" (paquete SFSF-GeoVictoria) para traducir TimeType de SFSF a TimeType de GeoVictoria | H4: Existe una versión del Value Mapping para test y otra para producción, con IDs distintos
A5: 4 | B5: groovy-script | C5: Construir filtro OData dinámico para la consulta a SFSF | D5: Principal | G5: Construye el $filter de la query a EmployeeTime combinando los tipos de ausencia ya mapeados y la fecha de última ejecución (variable "lastExecutionAbs_Test")
A6: 5 | B6: successfactors-odata-receiver | C6: Consultar ausencias en SFSF (EmployeeTime) | D6: Principal | E6: SFSF Test | F6: Receiver | G6: OData V2, entidad EmployeeTime; https://api55.sapsf.eu/odata/v2; credencial SFAPI_TEST (OAuth2 SAML Bearer Assertion) | H6: Aviso: en el tenant trial este adaptador certificado ha dado GenerationFailed en pruebas anteriores (ver fase5-diseno-iflow-status) — si no despliega, sustituir por HTTP genérico contra el mismo endpoint OData
A7: 6 | B7: groovy-script | C7: Acumular ausencias obtenidas en variable global | D7: Principal | G7: Guarda las ausencias devueltas por la query, de cara al envío posterior a GeoVictoria
A8: 7 | B8: router | C8: ¿Ejecución en modalidad Delta? | D8: Principal | G8: Condición sobre el modo de ejecución (Delta vs. Run Once/bajo demanda) | H8: Si NO es Delta, se salta la consulta al monitor de réplica (pasos 8-10)
A9: 8 | B9: successfactors-odata-receiver | C9: Consultar monitor de réplica SFSF (registros a reprocesar) | D9: Principal | E9: SFSF Test | F9: Receiver | G9: Entidad EmployeeDataReplicationConfirmation; filtro por Status="Reprocesar" | H9: Solo si el paso 7 es Delta=true
A10: 9 | B10: router | C10: ¿Hay registros marcados como "Reprocesar"? | D10: Principal | G10: Si no hay resultados, no se añade nada y continúa el flujo
A11: 10 | B11: groovy-script | C11: Añadir ausencias a reprocesar a la variable global | D11: Principal | G11: Obtiene las ausencias de los empleados marcados en el monitor de réplica y las añade a la variable global
A12: 11 | B12: router | C12: ¿Hay ausencias pendientes de envío? | D12: Principal | G12: Si la variable global de ausencias está vacía, finaliza el proceso | H12: Fin de proceso sin más acción si no hay ausencias
A13: 12 | B13: data-store-write | C13: Persistir relación ausencia SFSF↔GeoVictoria | D13: Principal | G13: Guarda ID ausencia SFSF, Tipo ausencia SFSF, ID tipo ausencia GV, Fecha inicio, Fecha fin — para detectar cancelaciones/modificaciones en ejecuciones futuras
A14: 13 | B14: local-process-call | C14: Invocar lógica de réplica de ausencias a GeoVictoria | D14: Principal | G14: Llama al Local Integration Process del paso 14
A15: 14 | B15: local-integration-process | C15: Lógica de negocio — réplica de ausencias a GeoVictoria | D15: Principal | G15: Contiene los pasos 15 a 27
A16: 15 | B16: http-receiver | C16: Obtener token de acceso de GeoVictoria | D16: 14 | E16: Https GeoVictoria | F16: Receiver | G16: POST https://customerapi.geovictoria.com/api/v1/Login; credencial GeoVictoria_Test (Básico por medio de token)
A17: 16 | B17: groovy-script | C17: Generar XML con las ausencias a replicar | D17: 14 | G17: A partir de la variable global de ausencias, genera un XML con un registro por ausencia
A18: 17 | B18: iterating-splitter | C18: Iterar cada registro de ausencia del XML | D18: 14 | G18: Un registro (ausencia) por iteración
A19: 18 | B19: content-modifier | C19: Extraer campos de la ausencia a properties | D19: 14 | G19: Guarda en properties/variables cada tag del XML (ID SFSF, tipo de ausencia, fechas inicio/fin...) — ver hoja "Content Modifier — Detalle", Orden 18
A20: 19 | B20: router | C20: Determinar operación: alta / cancelación / modificación | D20: 14 | G20: Chequeos sobre los campos extraídos para decidir la rama del flujo
A21: 20 | B21: content-modifier | C21: Construir body de alta o cancelación | D21: 14 | G21: Rama alta/cancelación: arma el request a enviar a GeoVictoria con los datos de la ausencia — ver hoja "Content Modifier — Detalle", Orden 20
A22: 21 | B22: http-receiver | C22: Enviar ausencia a GeoVictoria (alta/cancelación) | D22: 14 | E22: Https GeoVictoria | F22: Receiver | G22: POST https://customerapi.geovictoria.com/api/v1/TimeOff/; credencial GeoVictoria_Test | H22: Si falla, se registra el error y continúa con la siguiente ausencia
A23: 22 | B23: data-store-get | C23: Recuperar registro previo (rama modificación) | D23: 14 | G23: Busca en persistencia (paso 12), por ID de SFSF, el registro ya creado en GeoVictoria
A24: 23 | B24: http-receiver | C24: Borrar ausencia existente en GeoVictoria (rama modificación) | D24: 14 | E24: Https GeoVictoria | F24: Receiver | G24: DELETE https://customerapi.geovictoria.com/api/v1/TimeOff/; credencial GeoVictoria_Test | H24: Si el borrado falla, se registra el error y continúa con la siguiente
A25: 24 | B25: content-modifier | C25: Construir body de modificación (recreación) | D25: 14 | G25: Con los datos actualizados de SFSF, arma el nuevo request de alta — ver hoja "Content Modifier — Detalle", Orden 24 | H25: Solo si el borrado del paso 23 fue correcto
A26: 25 | B26: http-receiver | C26: Reenviar ausencia modificada a GeoVictoria | D26: 14 | E26: Https GeoVictoria | F26: Receiver | G26: POST https://customerapi.geovictoria.com/api/v1/TimeOff/; credencial GeoVictoria_Test
A27: 26 | B27: successfactors-odata-receiver | C27: Actualizar monitor de réplica en SFSF (por registro) | D27: 14 | E27: SFSF Test | F27: Receiver | G27: Entidad EmployeeDataReplicationConfirmation; marca el registro como replicado o erróneo según el resultado | H27: Mismo aviso GenerationFailed que el paso 5
A28: 27 | B28: groovy-script | C28: Actualizar variables globales (errores, mapeos, estado) | D28: 14 | G28: En función de la respuesta de GeoVictoria y de SFSF, actualiza la variable global de errores/estado para esta ausencia
A29: 28 | B29: router | C29: ¿Se han generado errores durante la réplica? | D29: Principal | G29: Basado en la variable global de errores acumulada tras el Local Integration Process (pasos 13-27)
A30: 29 | B30: content-modifier | C30: Construir email con el detalle de errores | D30: Principal | G30: Cuerpo del correo con el detalle de las ausencias que fallaron — ver hoja "Content Modifier — Detalle", Orden 29
A31: 30 | B31: send | C31: Enviar correo de notificación de error | D31: Principal | E31: URL_MAIL (smtp.office365.com) | G31: From: no_reply_SAP.CL@celeogroup.com | H31: Este paso y el siguiente (31) son el MISMO paso lógico (envío fire-and-forget) — usar el patrón "send" + adaptador Mail, no el patrón ServiceTask/ExternalCall estándar
A32: 31 | B32: mail-receiver | C32: Adaptador de envío de correo (SMTP) | D32: Principal | E32: URL_MAIL (smtp.office365.com) | F32: Receiver | G32: Servidor smtp.office365.com; remitente no_reply_SAP.CL@celeogroup.com | H32: Ver nota del paso 30
A33: 32 | B33: router | C33: ¿Ejecución en modalidad Delta? | D33: Principal | G33: Repite la comprobación del paso 7 para decidir si se actualiza la fecha de referencia
A34: 33 | B34: write-variables | C34: Actualizar fecha de última ejecución | D34: Principal | G34: Actualiza la variable "lastExecutionAbs_Test" en persistencia con la fecha de esta ejecución, para que la siguiente ejecución la tome como referencia | H34: Solo si Delta=true
A35: 34 | B35: error-subprocess | C35: Manejo de excepciones técnicas del proceso | D35: Principal | G35: Captura excepciones técnicas (timeout u otras) producidas durante la ejecución del flujo
A36: 35 | B36: content-modifier | C36: Construir email de excepción técnica | D36: 34 | G36: Cuerpo del correo con el detalle de la excepción capturada — ver hoja "Content Modifier — Detalle", Orden 35
A37: 36 | B37: send | C37: Enviar correo de excepción técnica | D37: 34 | E37: URL_MAIL (smtp.office365.com) | G37: From: no_reply_SAP.CL@celeogroup.com | H37: Mismo patrón que los pasos 30-31 (send + adaptador mail-receiver)
A38: 37 | B38: mail-receiver | C38: Adaptador de envío de correo (SMTP) — excepción técnica | D38: 34 | E38: URL_MAIL (smtp.office365.com) | F38: Receiver | G38: Servidor smtp.office365.com | H38: Ver nota del paso 36
D39: =IF($A39<>"","Principal","")
D40: =IF($A40<>"","Principal","")
...

Sheet Content Modifier — Detalle
A1: Orden del paso (columna "Orden" en "Pasos del iflow") | B1: Tipo de elemento | C1: Nombre (vacío si es Body) | D1: Valor o expresión | E1: Tipo de valor
A2: 18 | B2: Property | C2: idSfsf | D2: ${xpath://ID_Ausencia} | E2: Expresión (XPath)
A3: 18 | B3: Property | C3: tipoAusenciaSfsf | D3: ${xpath://Tipo_Ausencia} | E3: Expresión (XPath)
A4: 18 | B4: Property | C4: fechaInicio | D4: ${xpath://Fecha_Inicio} | E4: Expresión (XPath)
A5: 18 | B5: Property | C5: fechaFin | D5: ${xpath://Fecha_Fin} | E5: Expresión (XPath)
A6: 18 | B6: Property | C6: operacion | D6: ${xpath://Operacion} | E6: Expresión (XPath) — valores esperados: ALTA, CANCELACION, MODIFICACION (ver Paso 19)
A7: 20 | B7: Header | C7: Content-Type | D7: application/json | E7: Constante
A8: 20 | B8: Body | D8: (pendiente: el documento no incluye un ejemplo real del JSON esperado por POST /api/v1/TimeOff/ — completar con el schema real de GeoVictoria) | E8: Nota
A9: 24 | B9: Header | C9: Content-Type | D9: application/json | E9: Constante
A10: 24 | B10: Body | D10: (pendiente: mismo caso que el Paso 20 — recrear con los datos actualizados de SFSF tras el borrado) | E10: Nota
A11: 29 | B11: Header | C11: Content-Type | D11: text/plain | E11: Constante
A12: 29 | B12: Property | C12: from | D12: no_reply_SAP.CL@celeogroup.com | E12: Constante (parámetro From_Mail del documento)
A13: 29 | B13: Body | D13: (pendiente: el documento muestra un ejemplo de correo como imagen, no capturable como texto — el cuerpo debe listar las ausencias que fallaron) | E13: Nota
A14: 35 | B14: Header | C14: Content-Type | D14: text/plain | E14: Constante
A15: 35 | B15: Property | C15: from | D15: no_reply_SAP.CL@celeogroup.com | E15: Constante (parámetro From_Mail del documento)
A16: 35 | B16: Body | D16: (pendiente: el documento muestra un ejemplo de correo de excepción como imagen, no capturable como texto) | E16: Nota

Sheet Mapeos y Scripts — Detalle
A1: Orden del paso (columna "Orden" en "Pasos del iflow") | B1: Ejemplo de entrada | C1: Ejemplo de salida esperado | D1: Contexto / instrucciones adicionales
A2: 2 | B2: (sin datos de entrada — es el primer paso tras el Timer, arranque del proceso) | C2: { "company": "CL10", "person_id_external": "", "ep_credencial_geovic": "GeoVictoria_Test", "lastDateExecuteDefault": "2025-11-14T11:10:00Z", "address_timeoff": "https://customerapi.geovictoria.com/api/v1/TimeOff/", "Address": "https://api55preview.sapsf.eu", "URL_MAIL": "smtp.office365.com", "From_Mail": "no_reply_SAP.CL@celeogroup.com", "sistemaReplica": "GeoVictoria_Test", "valueMapping": "VM-Tipo_Absentismos_TEST", "var_delta": "lastExecutionAbs_Test" } | D2: REAL, no ilustrativo — son exactamente los parámetros que documenta el diseño técnico en "Parámetros externos de configuración". El script debe leerlos todos como properties/variables globales del proceso al arrancar.
A3: 3 | B3: { "TimeType": "<codigo SFSF, ver tabla VM-Tipo_Absentismos_TEST>" } | C3: { "TimeType": "<codigo GeoVictoria correspondiente>" } | D3: ILUSTRATIVO - el documento no da los codigos reales, solo confirma que existe la tabla de Value Mapping "VM-Tipo_Absentismos_TEST" (paquete SFSF-GeoVictoria) traduciendo el campo "TimeType" de SFSF al "TimeType" de GeoVictoria. Sustituir por los pares reales de esa tabla.
A4: 4 | B4: Tipos de ausencia ya mapeados (salida del Paso 3) + fecha de última ejecución (variable "lastExecutionAbs_Test", o el parámetro "lastDateExecuteDefault" si es la primera ejecución) | C4: TimeType eq 'ENF' or TimeType eq 'VAC' and lastModifiedDateTime ge datetime'2025-11-14T11:10:00Z' | D4: ILUSTRATIVO — el documento describe que se construye "dinámicamente el where de la query" combinando estos dos datos, pero no incluye la sintaxis $filter real ni el nombre exacto del campo de fecha en la entidad EmployeeTime de SFSF. Verificar el nombre de campo real contra el $metadata de SFSF.
A5: 6 | B5: Resultado de la query OData a EmployeeTime (array de registros de ausencia) | C5: (variable global acumulando, por cada registro: ID ausencia SFSF, Tipo de ausencia SFSF, Fecha inicio, Fecha fin — mismos campos que ya documenta la persistencia del Paso 12) | D5: PARCIALMENTE REAL — el documento dice "se van guardando en una variable global, de cara al posterior envío a GeoVictoria" sin detallar la estructura interna; los nombres de campo sí están grounded en la sección de Persistencia del documento.
A6: 10 | B6: Resultado de la consulta al monitor de réplica de SFSF (registros con Status="Reprocesar") | C6: (los mismos registros añadidos a la variable global de ausencias del Paso 6, con la misma estructura) | D6: REAL — el documento dice textualmente: "en el caso de encontrar registros, se obtienen las ausencias de los empleados seleccionados y éstas se añaden a la variable global".
A7: 16 | B7: (variable global con la lista de ausencias obtenidas de SFSF - ver Paso 5/6/10) | C7: <row><cell>ID_Ausencia</cell><cell>...</cell></row><row><cell>Tipo_Ausencia</cell><cell>...</cell></row><row><cell>Fecha_Inicio</cell><cell>...</cell></row><row><cell>Fecha_Fin</cell><cell>...</cell></row> | D7: ILUSTRATIVO - el documento describe que este script "procesa la variable global... y genera un XML con esta información" pero no incluye el XSD/estructura real del XML. Estructura de ejemplo basada en los campos de persistencia ya documentados (Paso 12).
A8: 27 | B8: Respuesta HTTP de GeoVictoria (código de estado + body del Paso 21/23/25) y de la actualización en SFSF (Paso 26) | C8: (variable global de errores marca esta ausencia como OK o con fallo; variable de mapeos de absentismo y del monitor de réplica actualizadas en consecuencia) | D8: REAL — el documento dice textualmente: "en función de la respuesta obtenida por GeoVictoria, se gestionarán las variables globales de errores, mapeos de absentismo y del monitor de réplica", pero no da el formato exacto de esas variables.

Sheet Catálogo de componentes
A1: Id técnico (usar este valor en "Pasos del iflow") | B1: Nombre | C1: Categoría | D1: Cuándo usarlo
A2: Adaptadores — llamada a sistemas externos (Receiver)
A3: http-receiver | B3: Adaptador HTTP (Receiver) | C3: Adaptadores | D3: Llamar a un servicio HTTP/REST genérico
A4: soap-receiver | B4: Adaptador SOAP (Receiver) | C4: Adaptadores | D4: Llamar a un servicio SOAP/WSDL
A5: jdbc-receiver | B5: Adaptador JDBC (Receiver) | C5: Adaptadores | D5: Consultar/escribir en una base de datos SQL
A6: sftp-receiver | B6: Adaptador SFTP (Receiver) | C6: Adaptadores | D6: Escribir/leer un fichero en un servidor SFTP
A7: as2-receiver | B7: Adaptador AS2 (Receiver) | C7: Adaptadores | D7: Intercambio B2B vía AS2
A8: idoc-receiver | B8: Adaptador IDoc (Receiver) | C8: Adaptadores | D8: Enviar un IDoc a SAP ECC/S4
A9: jms-receiver | B9: Adaptador JMS (Receiver) | C9: Adaptadores | D9: Publicar en una cola JMS
A10: mail-receiver | B10: Adaptador Mail/SMTP (Receiver) | C10: Adaptadores | D10: Enviar un correo — usar siempre junto al paso 'send'
A11: odata-v2-receiver | B11: Adaptador OData V2 genérico (Receiver) | C11: Adaptadores | D11: Llamar a un servicio OData V2 no certificado
A12: odata-v4-receiver | B12: Adaptador OData V4 genérico (Receiver) | C12: Adaptadores | D12: Llamar a un servicio OData V4
A13: processdirect-receiver | B13: Adaptador ProcessDirect (Receiver) | C13: Adaptadores | D13: Llamar a otro iflow del mismo tenant
A14: successfactors-odata-receiver | B14: Adaptador SuccessFactors OData V2 (Receiver) | C14: Adaptadores | D14: Llamar a SuccessFactors vía OData V2 — requiere paquete certificado instalado
A15: successfactors-soap-receiver-compoundemployee | B15: Adaptador SuccessFactors SOAP (Receiver) | C15: Adaptadores | D15: Consultar CompoundEmployee en SuccessFactors vía SOAP
A16: Adaptadores — exponer/recibir de sistemas externos (Sender)
A17: soap-sender | B17: Adaptador SOAP (Sender) | C17: Adaptadores | D17: Exponer un servicio SOAP — indica la ruta a publicar en "Configuración clave"
A18: sftp-sender | B18: Adaptador SFTP (Sender) | C18: Adaptadores | D18: Recoger ficheros de un servidor SFTP
A19: pollingsftp-sender | B19: Adaptador Polling SFTP (Sender) | C19: Adaptadores | D19: Recoger ficheros de SFTP por sondeo periódico
A20: as2-sender | B20: Adaptador AS2 (Sender) | C20: Adaptadores | D20: Recibir intercambios B2B vía AS2
A21: idoc-sender | B21: Adaptador IDoc (Sender) | C21: Adaptadores | D21: Recibir IDocs desde SAP ECC/S4
A22: jms-sender | B22: Adaptador JMS (Sender) | C22: Adaptadores | D22: Consumir de una cola JMS
A23: mail-sender-imap | B23: Adaptador Mail/IMAP (Sender) | C23: Adaptadores | D23: Recoger correos vía IMAP
A24: mail-sender-pop3 | B24: Adaptador Mail/POP3 (Sender) | C24: Adaptadores | D24: Recoger correos vía POP3
A25: odata-v2-sender | B25: Adaptador OData V2 genérico (Sender) | C25: Adaptadores | D25: Exponer un servicio OData V2 — indica la ruta a publicar en "Configuración clave"
A26: processdirect-sender | B26: Adaptador ProcessDirect (Sender) | C26: Adaptadores | D26: Recibir llamadas de otro iflow del mismo tenant
A27: Inicio del proceso
A28: timer-start-event | B28: Timer Start Event | C28: Inicio | D28: Arrancar el iflow por planificación (diaria, cada N horas, cron...)
A29: Pasos de flujo y control
A30: groovy-script | B30: Script Groovy | C30: Flujo | D30: Lógica custom en código — rellena también la hoja "Mapeos y Scripts — Detalle"
A31: content-modifier | B31: Content Modifier | C31: Flujo | D31: Fijar headers/properties/body — rellena también la hoja "Content Modifier — Detalle"
A32: content-enricher-lookup | B32: Content Enricher con Lookup | C32: Flujo | D32: Enriquecer el mensaje consultando otro sistema antes de continuar
A33: message-mapping | B33: Message Mapping | C33: Flujo | D33: Mapeo gráfico de un formato a otro — rellena también la hoja "Mapeos y Scripts — Detalle"
A34: router | B34: Router / Exclusive Gateway | C34: Flujo | D34: Bifurcar el flujo según una condición (indícala en "Condición / Notas")
A35: splitter | B35: Splitter | C35: Flujo | D35: Dividir un mensaje en varios (p. ej. una lista en N mensajes)
A36: gather | B36: Gather | C36: Flujo | D36: Recomponer los mensajes tras un Splitter
A37: join | B37: Join | C37: Flujo | D37: Unir ramas paralelas de un Multicast
A38: multicast-parallel | B38: Multicast paralelo | C38: Flujo | D38: Enviar el mismo mensaje a varias ramas en paralelo
A39: multicast-sequential | B39: Multicast secuencial | C39: Flujo | D39: Enviar el mismo mensaje a varias ramas en orden
A40: filter | B40: Filter | C40: Flujo | D40: Filtrar partes del mensaje (p. ej. un nodo XML)
...

Sheet _listaIds
A1: http-receiver
A2: soap-receiver
A3: jdbc-receiver
A4: sftp-receiver
A5: as2-receiver
A6: idoc-receiver
A7: jms-receiver
A8: mail-receiver
A9: odata-v2-receiver
A10: odata-v4-receiver
A11: processdirect-receiver
A12: successfactors-odata-receiver
... A64: pgp-decrypt

Sheet _ordenesContenedor
A1: Principal
A2: =IF(OR('Pasos del iflow'!B2="local-integration-process",'Pasos del iflow'!B2="error-subprocess"),'Pasos del iflow'!A2,"")
A3: =IF(OR('Pasos del iflow'!B3="local-integration-process",'Pasos del iflow'!B3="error-subprocess"),'Pasos del iflow'!A3,"")
A4: =IF(OR('Pasos del iflow'!B4="local-integration-process",'Pasos del iflow'!B4="error-subprocess"),'Pasos del iflow'!A4,"")
A5: =IF(OR('Pasos del iflow'!B5="local-integration-process",'Pasos del iflow'!B5="error-subprocess"),'Pasos del iflow'!A5,"")
A6: =IF(OR('Pasos del iflow'!B6="local-integration-process",'Pasos del iflow'!B6="error-subprocess"),'Pasos del iflow'!A6,"")
A7: =IF(OR('Pasos del iflow'!B7="local-integration-process",'Pasos del iflow'!B7="error-subprocess"),'Pasos del iflow'!A7,"")
A8: =IF(OR('Pasos del iflow'!B8="local-integration-process",'Pasos del iflow'!B8="error-subprocess"),'Pasos del iflow'!A8,"")
A9: =IF(OR('Pasos del iflow'!B9="local-integration-process",'Pasos del iflow'!B9="error-subprocess"),'Pasos del iflow'!A9,"")
A10: =IF(OR('Pasos del iflow'!B10="local-integration-process",'Pasos del iflow'!B10="error-subprocess"),'Pasos del iflow'!A10,"")
A11: =IF(OR('Pasos del iflow'!B11="local-integration-process",'Pasos del iflow'!B11="error-subprocess"),'Pasos del iflow'!A11,"")
A12: =IF(OR('Pasos del iflow'!B12="local-integration-process",'Pasos del iflow'!B12="error-subprocess"),'Pasos del iflow'!A12,"")
A13: =IF(OR('Pasos del iflow'!B13="local-integration-process",'Pasos del iflow'!B13="error-subprocess"),'Pasos del iflow'!A13,"")
... A300: =IF(OR('Pasos del iflow'!B300="local-integration-process",'Pasos del iflow'!B300="error-subprocess"),'Pasos del iflow'!A300,"")

Sheet _ordenesCM
A1: =IF('Pasos del iflow'!B1="content-modifier",'Pasos del iflow'!A1,"")
A2: =IF('Pasos del iflow'!B2="content-modifier",'Pasos del iflow'!A2,"")
A3: =IF('Pasos del iflow'!B3="content-modifier",'Pasos del iflow'!A3,"")
A4: =IF('Pasos del iflow'!B4="content-modifier",'Pasos del iflow'!A4,"")
A5: =IF('Pasos del iflow'!B5="content-modifier",'Pasos del iflow'!A5,"")
A6: =IF('Pasos del iflow'!B6="content-modifier",'Pasos del iflow'!A6,"")
A7: =IF('Pasos del iflow'!B7="content-modifier",'Pasos del iflow'!A7,"")
A8: =IF('Pasos del iflow'!B8="content-modifier",'Pasos del iflow'!A8,"")
A9: =IF('Pasos del iflow'!B9="content-modifier",'Pasos del iflow'!A9,"")
A10: =IF('Pasos del iflow'!B10="content-modifier",'Pasos del iflow'!A10,"")
A11: =IF('Pasos del iflow'!B11="content-modifier",'Pasos del iflow'!A11,"")
A12: =IF('Pasos del iflow'!B12="content-modifier",'Pasos del iflow'!A12,"")
... A300: =IF('Pasos del iflow'!B300="content-modifier",'Pasos del iflow'!A300,"")

Sheet _ordenesMS
A1: =IF(OR('Pasos del iflow'!B1="message-mapping",'Pasos del iflow'!B1="groovy-script"),'Pasos del iflow'!A1,"")
A2: =IF(OR('Pasos del iflow'!B2="message-mapping",'Pasos del iflow'!B2="groovy-script"),'Pasos del iflow'!A2,"")
A3: =IF(OR('Pasos del iflow'!B3="message-mapping",'Pasos del iflow'!B3="groovy-script"),'Pasos del iflow'!A3,"")
A4: =IF(OR('Pasos del iflow'!B4="message-mapping",'Pasos del iflow'!B4="groovy-script"),'Pasos del iflow'!A4,"")
A5: =IF(OR('Pasos del iflow'!B5="message-mapping",'Pasos del iflow'!B5="groovy-script"),'Pasos del iflow'!A5,"")
A6: =IF(OR('Pasos del iflow'!B6="message-mapping",'Pasos del iflow'!B6="groovy-script"),'Pasos del iflow'!A6,"")
A7: =IF(OR('Pasos del iflow'!B7="message-mapping",'Pasos del iflow'!B7="groovy-script"),'Pasos del iflow'!A7,"")
A8: =IF(OR('Pasos del iflow'!B8="message-mapping",'Pasos del iflow'!B8="groovy-script"),'Pasos del iflow'!A8,"")
A9: =IF(OR('Pasos del iflow'!B9="message-mapping",'Pasos del iflow'!B9="groovy-script"),'Pasos del iflow'!A9,"")
A10: =IF(OR('Pasos del iflow'!B10="message-mapping",'Pasos del iflow'!B10="groovy-script"),'Pasos del iflow'!A10,"")
A11: =IF(OR('Pasos del iflow'!B11="message-mapping",'Pasos del iflow'!B11="groovy-script"),'Pasos del iflow'!A11,"")
A12: =IF(OR('Pasos del iflow'!B12="message-mapping",'Pasos del iflow'!B12="groovy-script"),'Pasos del iflow'!A12,"")
... A300: =IF(OR('Pasos del iflow'!B300="message-mapping",'Pasos del iflow'!B300="groovy-script"),'Pasos del iflow'!A300,"")
